
2024-04-04 00:00:17,814 An error has occured: 401 Unauthorized
Unauthorized
Traceback (most recent call last):
  File "main.py", line 187, in main
    post_to_twitter(api_v2,quote,include_datetime)
  File "main.py", line 90, in post_to_twitter
    tweet = api_v2.create_tweet(media_ids=media_ids,text=quote)
  File "/home/runner/cdotquote-bot/venv/lib/python3.10/site-packages/tweepy/client.py", line 835, in create_tweet
    return self._make_request(
  File "/home/runner/cdotquote-bot/venv/lib/python3.10/site-packages/tweepy/client.py", line 129, in _make_request
    response = self.request(method, route, params=request_params,
  File "/home/runner/cdotquote-bot/venv/lib/python3.10/site-packages/tweepy/client.py", line 98, in request
    raise Unauthorized(response)
tweepy.errors.Unauthorized: 401 Unauthorized
Unauthorized
